Workbook

Sheet Info
A1: Tahap 2 — Project Planning: Kedai Pujasera Digital
A2: Kelompok 11 · Teknik Informatika · Universitas Samudra · Manajemen Proyek Perangkat Lunak · Dosen: Cut Alna Fadhilla, S.Kom., M.Sc
B4: Tim
B5: Andi Saputra (230504081), Muhammad Hafiz Akbar (230504077), Arya Diansyah (230504063), Kharisa Ariyana (230504069)
B6: Tanggal mulai jadwal | C6: 46314 | D6: Senin; 17–18 Okt akhir pekan. Ubah di sini bila mulai berbeda (judul bulan di Gantt perlu disesuaikan).
B8: Isi workbook
B11: Tenggat | C11: Tahap | D11: Pekerjaan selesai (jadwal) | E11: Sisa hari kalender | F11: Status
B12: 46319 | C12: Tahap 2 — Project Planning | D12: ='Jadwal Gantt'!H12 -> 46318 | E12: =B12-D12 -> 1 | F12: =IF(D12<=B12,"Sesuai tenggat","Melewati tenggat") -> Sesuai tenggat
B13: 46326 | C13: Tahap 3 — Project Execution | D13: =MAX('Jadwal Gantt'!H19,'Jadwal Gantt'!H23,'Jadwal Gantt'!H28) -> 46325 | E13: =B13-D13 -> 1 | F13: =IF(D13<=B13,"Sesuai tenggat","Melewati tenggat") -> Sesuai tenggat
B14: 46340 | C14: Tahap 4 — Monitoring & Controlling | D14: ='Jadwal Gantt'!H47 -> 46339 | E14: =B14-D14 -> 1 | F14: =IF(D14<=B14,"Sesuai tenggat","Melewati tenggat") -> Sesuai tenggat
B15: 46354 | C15: Tahap 5 — Project Closure | D15: =MAX('Jadwal Gantt'!H37,'Jadwal Gantt'!H48) -> 46353 | E15: =B15-D15 -> 1 | F15: =IF(D15<=B15,"Sesuai tenggat","Melewati tenggat") -> Sesuai tenggat
B16: Tahap 3 diukur dari selesainya analisis kebutuhan, perancangan, dan lingkungan pengembangan; Tahap 4 dari kompilasi laporan monitoring; Tahap 5 dari dokumentasi dan penutupan.
B18: Isi workbook
B19: Jadwal Gantt | C19: Project Schedule / Gantt Chart: aktivitas, durasi, mulai–selesai, dependensi, milestone
B20: Resource Plan | C20: Resource & Responsibility Plan: anggota, peran, tanggung jawab, matriks RACI, kebutuhan sumber daya
B21: Effort Manday | C21: Effort Estimation (manday) per aktivitas berdasarkan WBS
B22: Biaya | C22: Project Cost Estimation: tenaga kerja, perangkat/layanan, overhead, cadangan
B23: Risk Register | C23: Risiko, probabilitas, dampak, skor, dan strategi mitigasi
B25: Asumsi yang dipakai
B26: 1 | C26: Hari kerja Senin–Jumat; hari libur nasional tidak diperhitungkan. Inisiasi (WBS 1) sudah selesai sebelum jadwal ini.
B27: 2 | C27: Estimasi manday memakai PERT tiga titik, E = (O + 4M + P) ÷ 6. Angka O, M, P adalah perkiraan tim.
B28: 3 | C28: Durasi = manday ÷ jumlah orang, dibulatkan ke atas. Rapat koordinasi dijadwalkan tiap Rabu.
B29: 4 | C29: Tarif Rp100.000 per manday di sheet Biaya adalah asumsi nilai setara tenaga kerja, bukan pembayaran nyata.
B30: 5 | C30: Harga kuota internet, transportasi, dan cetak di sheet Biaya adalah asumsi. Ganti dengan angka sebenarnya.
B31: 6 | C31: Probabilitas dan dampak risiko adalah penilaian awal tim, bukan hasil pengukuran.
B32: 7 | C32: Kode WBS 2.5–2.9, 8, dan 9 ditambahkan sesuai output Tahap 2, 4, dan 5 (di luar WBS awal pada laporan Bab IV).
B33: 8 | C33: Pembagian PIC pada jadwal ini menyesuaikan beban kerja, sehingga ada perbedaan kecil dari Tabel 4.3 di laporan awal.
B35: Kode warna
B36: Biru = nilai input yang boleh diubah
B37: Hitam = rumus
B38: Hijau = tautan dari sheet lain
B39: Latar kuning = asumsi kunci / sel yang perlu dicek

Sheet Jadwal Gantt
A1: Project Schedule / Gantt Chart — Kedai Pujasera Digital
A2: Hari kerja Senin–Jumat. Tanggal mulai/selesai dihitung otomatis dari durasi (sheet Effort Manday) dan dependensi Finish-to-Start (FS).
A4: Legenda: | C4: Biru = aktivitas | D4: Hijau = rapat | J4: Oktober 2026 | W4: November 2026
C5: Hitam tebal = ringkasan fase | D5: ◆ = tenggat dosen | J5: =CHOOSE(WEEKDAY(J6,2),"S","S","R","K","J","S","M") -> S | K5: =CHOOSE(WEEKDAY(K6,2),"S","S","R","K","J","S","M") -> S | L5: =CHOOSE(WEEKDAY(L6,2),"S","S","R","K","J","S","M") -> R | M5: =CHOOSE(WEEKDAY(M6,2),"S","S","R","K","J","S","M") -> K | N5: =CHOOSE(WEEKDAY(N6,2),"S","S","R","K","J","S","M") -> J | O5: =CHOOSE(WEEKDAY(O6,2),"S","S","R","K","J","S","M") -> S | P5: =CHOOSE(WEEKDAY(P6,2),"S","S","R","K","J","S","M") -> M | Q5: =CHOOSE(WEEKDAY(Q6,2),"S","S","R","K","J","S","M") -> S | ... AX5: =CHOOSE(WEEKDAY(AX6,2),"S","S","R","K","J","S","M") -> S
A6: No | B6: Kode WBS | C6: Aktivitas | D6: PIC | E6: Durasi (hari kerja) | F6: Dependensi | G6: Mulai | H6: Selesai | I6: Jenis | J6: =Info!$C$6 -> 46314 | K6: =J6+1 -> 46315 | L6: =K6+1 -> 46316 | M6: =L6+1 -> 46317 | N6: =M6+1 -> 46318 | O6: =N6+1 -> 46319 | P6: =O6+1 -> 46320 | Q6: =P6+1 -> 46321 | R6: =Q6+1 -> 46322 | ... AX6: =AW6+1 -> 46354
C7: MILESTONE (TENGGAT DOSEN) | I7: Judul
A8: 1 | B8: M2 | C8: Tahap 2 Project Planning dikumpulkan | D8: Semua | F8: Tanggal tetap (dosen) | G8: =Info!$B$12 -> 46319 | H8: =G8 -> 46319 | I8: Milestone | J8: =IF(J$6=$G8,"◆","") | K8: =IF(K$6=$G8,"◆","") | L8: =IF(L$6=$G8,"◆","") | M8: =IF(M$6=$G8,"◆","") | N8: =IF(N$6=$G8,"◆","") | O8: =IF(O$6=$G8,"◆","") -> ◆ | P8: =IF(P$6=$G8,"◆","") | Q8: =IF(Q$6=$G8,"◆","") | ... AX8: =IF(AX$6=$G8,"◆","")
A9: 2 | B9: M3 | C9: Tahap 3 Project Execution dikumpulkan | D9: Semua | F9: Tanggal tetap (dosen) | G9: =Info!$B$13 -> 46326 | H9: =G9 -> 46326 | I9: Milestone | J9: =IF(J$6=$G9,"◆","") | K9: =IF(K$6=$G9,"◆","") | L9: =IF(L$6=$G9,"◆","") | M9: =IF(M$6=$G9,"◆","") | N9: =IF(N$6=$G9,"◆","") | O9: =IF(O$6=$G9,"◆","") | P9: =IF(P$6=$G9,"◆","") | Q9: =IF(Q$6=$G9,"◆","") | ... AX9: =IF(AX$6=$G9,"◆","")
A10: 3 | B10: M4 | C10: Tahap 4 Monitoring & Controlling dikumpulkan | D10: Semua | F10: Tanggal tetap (dosen) | G10: =Info!$B$14 -> 46340 | H10: =G10 -> 46340 | I10: Milestone | J10: =IF(J$6=$G10,"◆","") | K10: =IF(K$6=$G10,"◆","") | L10: =IF(L$6=$G10,"◆","") | M10: =IF(M$6=$G10,"◆","") | N10: =IF(N$6=$G10,"◆","") | O10: =IF(O$6=$G10,"◆","") | P10: =IF(P$6=$G10,"◆","") | Q10: =IF(Q$6=$G10,"◆","") | ... AX10: =IF(AX$6=$G10,"◆","")
A11: 4 | B11: M5 | C11: Tahap 5 Project Closure dan presentasi final | D11: Semua | F11: Tanggal tetap (dosen) | G11: =Info!$B$15 -> 46354 | H11: =G11 -> 46354 | I11: Milestone | J11: =IF(J$6=$G11,"◆","") | K11: =IF(K$6=$G11,"◆","") | L11: =IF(L$6=$G11,"◆","") | M11: =IF(M$6=$G11,"◆","") | N11: =IF(N$6=$G11,"◆","") | O11: =IF(O$6=$G11,"◆","") | P11: =IF(P$6=$G11,"◆","") | Q11: =IF(Q$6=$G11,"◆","") | ... AX11: =IF(AX$6=$G11,"◆","") -> ◆
C12: PERENCANAAN (TAHAP 2 — PROJECT PLANNING) | E12: =NETWORKDAYS(G12,H12) -> 5 | G12: =MIN(G13:G18) -> 46314 | H12: =MAX(H13:H18) -> 46318 | I12: Ringkasan
A13: 5 | B13: 2.3 | C13: Menyusun jadwal kegiatan dan Gantt Chart | D13: Hafiz | E13: ='Effort Manday'!M6 -> 2 | F13: Mulai proyek | G13: =Info!$C$6 -> 46314 | H13: =WORKDAY(G13,E13-1) -> 46315 | I13: Aktivitas
A14: 6 | B14: 2.5 | C14: Menyusun Resource & Responsibility Plan | D14: Andi | E14: ='Effort Manday'!M7 -> 2 | F14: Mulai proyek | G14: =Info!$C$6 -> 46314 | H14: =WORKDAY(G14,E14-1) -> 46315 | I14: Aktivitas
A15: 7 | B15: 2.6 | C15: Menyusun estimasi usaha (manday) | D15: Kharisa | E15: ='Effort Manday'!M8 -> 1 | F15: FS: 2.3 | G15: =WORKDAY(H13,1) -> 46316 | H15: =WORKDAY(G15,E15-1) -> 46316 | I15: Aktivitas
A16: 8 | B16: 2.7 | C16: Menyusun estimasi biaya proyek | D16: Hafiz | E16: ='Effort Manday'!M9 -> 1 | F16: FS: 2.6 | G16: =WORKDAY(H15,1) -> 46317 | H16: =WORKDAY(G16,E16-1) -> 46317 | I16: Aktivitas
A17: 9 | B17: 2.8 | C17: Menyusun Risk Register | D17: Arya | E17: ='Effort Manday'!M10 -> 2 | F17: Mulai proyek | G17: =Info!$C$6 -> 46314 | H17: =WORKDAY(G17,E17-1) -> 46315 | I17: Aktivitas
A18: 10 | B18: 2.9 | C18: Review, kompilasi, dan unggah dokumen Tahap 2 ke GitHub | D18: Andi, Hafiz | E18: ='Effort Manday'!M11 -> 1 | F18: FS: 2.5, 2.7, 2.8 | G18: =WORKDAY(MAX(H14,H16,H17),1) -> 46318 | H18: =WORKDAY(G18,E18-1) -> 46318 | I18: Aktivitas
C19: ANALISIS KEBUTUHAN | E19: =NETWORKDAYS(G19,H19) -> 4 | G19: =MIN(G20:G22) -> 46321 | H19: =MAX(H20:H22) -> 46324 | I19: Ringkasan
A20: 11 | B20: 3.1 | C20: Mengumpulkan data menu, harga, foto, dan informasi kedai | D20: Kharisa | E20: ='Effort Manday'!M12 -> 3 | F20: FS: 2.9 | G20: =WORKDAY(H18,1) -> 46321 | H20: =WORKDAY(G20,E20-1) -> 46323 | I20: Aktivitas
A21: 12 | B21: 3.2 | C21: Menentukan kebutuhan pengguna | D21: Andi | E21: ='Effort Manday'!M13 -> 2 | F21: FS: 2.9 | G21: =WORKDAY(H18,1) -> 46321 | H21: =WORKDAY(G21,E21-1) -> 46322 | I21: Aktivitas
A22: 13 | B22: 3.3 | C22: Menyusun kebutuhan fungsional dan nonfungsional | D22: Andi | E22: ='Effort Manday'!M14 -> 2 | F22: FS: 3.2 | G22: =WORKDAY(H21,1) -> 46323 | H22: =WORKDAY(G22,E22-1) -> 46324 | I22: Aktivitas
C23: PERANCANGAN | E23: =NETWORKDAYS(G23,H23) -> 5 | G23: =MIN(G24:G26) -> 46321 | H23: =MAX(H24:H26) -> 46325 | I23: Ringkasan
A24: 14 | B24: 4.1 | C24: Merancang struktur informasi/halaman | D24: Arya | E24: ='Effort Manday'!M15 -> 2 | F24: FS: 2.9 | G24: =WORKDAY(H18,1) -> 46321 | H24: =WORKDAY(G24,E24-1) -> 46322 | I24: Aktivitas
A25: 15 | B25: 4.2 | C25: Merancang tampilan (wireframe/mockup) | D25: Arya | E25: ='Effort Manday'!M16 -> 3 | F25: FS: 4.1, 3.2 | G25: =WORKDAY(MAX(H24,H21),1) -> 46323 | H25: =WORKDAY(G25,E25-1) -> 46325 | I25: Aktivitas
A26: 16 | B26: 4.3 | C26: Menentukan teknologi yang digunakan | D26: Hafiz | E26: ='Effort Manday'!M17 -> 1 | F26: FS: 2.9 | G26: =WORKDAY(H18,1) -> 46321 | H26: =WORKDAY(G26,E26-1) -> 46321 | I26: Aktivitas
C27: PENGEMBANGAN | E27: =NETWORKDAYS(G27,H27) -> 14 | G27: =MIN(G28:G31) -> 46322 | H27: =MAX(H28:H31) -> 46339 | I27: Ringkasan
A28: 17 | B28: 5.1 | C28: Menyiapkan lingkungan pengembangan | D28: Hafiz | E28: ='Effort Manday'!M18 -> 1 | F28: FS: 4.3 | G28: =WORKDAY(H26,1) -> 46322 | H28: =WORKDAY(G28,E28-1) -> 46322 | I28: Aktivitas
A29: 18 | B29: 5.2 | C29: Membuat tampilan halaman | D29: Arya | E29: ='Effort Manday'!M19 -> 6 | F29: FS: 4.2, 5.1 | G29: =WORKDAY(MAX(H25,H28),1) -> 46328 | H29: =WORKDAY(G29,E29-1) -> 46335 | I29: Aktivitas
A30: 19 | B30: 5.3 | C30: Memasukkan menu, foto, harga, dan informasi kedai | D30: Kharisa | E30: ='Effort Manday'!M20 -> 4 | F30: FS: 5.2, 3.1 | G30: =WORKDAY(MAX(H29,H20),1) -> 46336 | H30: =WORKDAY(G30,E30-1) -> 46339 | I30: Aktivitas
A31: 20 | B31: 5.4 | C31: Mengelola versi kode melalui GitHub (berkelanjutan) | D31: Hafiz | E31: ='Effort Manday'!M21 -> 14 | F31: SS: 5.1 | G31: =G28 -> 46322 | H31: =WORKDAY(G31,E31-1) -> 46339 | I31: Aktivitas
C32: PENGUJIAN | E32: =NETWORKDAYS(G32,H32) -> 15 | G32: =MIN(G33:G36) -> 46325 | H32: =MAX(H33:H36) -> 46345 | I32: Ringkasan
A33: 21 | B33: 6.1 | C33: Menyusun skenario pengujian | D33: Andi | E33: ='Effort Manday'!M22 -> 2 | F33: FS: 3.3 | G33: =WORKDAY(H22,1) -> 46325 | H33: =WORKDAY(G33,E33-1) -> 46328 | I33: Aktivitas
A34: 22 | B34: 6.2 | C34: Menguji tampilan dan fungsi | D34: Arya, Andi | E34: ='Effort Manday'!M23 -> 2 | F34: FS: 5.3, 6.1 | G34: =WORKDAY(MAX(H30,H33),1) -> 46342 | H34: =WORKDAY(G34,E34-1) -> 46343 | I34: Aktivitas
A35: 23 | B35: 6.3 | C35: Memperbaiki temuan pengujian | D35: Kharisa, Hafiz | E35: ='Effort Manday'!M24 -> 2 | F35: FS: 6.2 | G35: =WORKDAY(H34,1) -> 46344 | H35: =WORKDAY(G35,E35-1) -> 46345 | I35: Aktivitas
A36: 24 | B36: 6.4 | C36: Meminta masukan dari pemilik kedai | D36: Andi | E36: ='Effort Manday'!M25 -> 1 | F36: FS: 6.2 | G36: =WORKDAY(H34,1) -> 46344 | H36: =WORKDAY(G36,E36-1) -> 46344 | I36: Aktivitas
C37: DOKUMENTASI | E37: =NETWORKDAYS(G37,H37) -> 9 | G37: =MIN(G38:G41) -> 46342 | H37: =MAX(H38:H41) -> 46352 | I37: Ringkasan
A38: 25 | B38: 7.1 | C38: Menyusun laporan akhir proyek | D38: Andi | E38: ='Effort Manday'!M26 -> 4 | F38: FS: 6.3, 6.4 | G38: =WORKDAY(MAX(H35,H36),1) -> 46346 | H38: =WORKDAY(G38,E38-1) -> 46351 | I38: Aktivitas
A39: 26 | B39: 7.2 | C39: Mendokumentasikan repositori dan cara penggunaan | D39: Hafiz | E39: ='Effort Manday'!M27 -> 2 | F39: FS: 5.4 | G39: =WORKDAY(H31,1) -> 46342 | H39: =WORKDAY(G39,E39-1) -> 46343 | I39: Aktivitas
A40: 27 | B40: 7.3 | C40: Menyiapkan presentasi final | D40: Kharisa | E40: ='Effort Manday'!M28 -> 3 | F40: FS: 9.1 | G40: =WORKDAY(H49,1) -> 46350 | H40: =WORKDAY(G40,E40-1) -> 46352 | I40: Aktivitas
A41: 28 | B41: 7.4 | C41: Menyusun evaluasi pencapaian dan Lessons Learned | D41: Arya, Kharisa | E41: ='Effort Manday'!M29 -> 1 | F41: FS: 9.1 | G41: =WORKDAY(H49,1) -> 46350 | H41: =WORKDAY(G41,E41-1) -> 46350 | I41: Aktivitas
...

Sheet Resource Plan
A1: Resource & Responsibility Plan — Kedai Pujasera Digital
A2: Peran dan pembagian tanggung jawab bersifat usulan dan bisa disesuaikan kelompok.
A4: 1. Anggota tim, peran, dan tanggung jawab
A5: No | B5: Nama | C5: NIM | D5: Peran proyek | E5: Tanggung jawab utama | F5: Kode WBS yang dipegang | G5: Total manday
A6: 1 | B6: Andi Saputra | C6: 230504081 | D6: Analis kebutuhan dan penyusun laporan | E6: Analisis kebutuhan pengguna, skenario pengujian, masukan pemilik kedai, laporan akhir, review dokumen | F6: 2.5, 2.9, 3.2, 3.3, 6.1, 6.2, 6.4, 7.1, 8.3, 8.5, 9.2 + rapat mingguan | G6: ='Effort Manday'!N43 -> 16.575
A7: 2 | B7: Muhammad Hafiz Akbar | C7: 230504077 | D7: Pengelola repositori dan pengembang | E7: Jadwal dan biaya proyek, teknologi, lingkungan pengembangan, pengelolaan GitHub, finalisasi produk | F7: 2.3, 2.7, 2.9, 4.3, 5.1, 5.4, 6.3, 7.2, 8.1, 9.1, 9.2 + rapat mingguan | G7: ='Effort Manday'!O43 -> 14.225
A8: 3 | B8: Arya Diansyah | C8: 230504063 | D8: Perancang tampilan dan pengembang UI | E8: Risk register, struktur halaman, wireframe/mockup, pembuatan tampilan, pengujian, evaluasi | F8: 2.8, 4.1, 4.2, 5.2, 6.2, 7.4, 8.4, 9.1, 9.2 + rapat mingguan | G8: ='Effort Manday'!P43 -> 17.608333
A9: 4 | B9: Kharisa Ariyana | C9: 230504069 | D9: Pengelola konten dan presentasi | E9: Estimasi manday, pengumpulan data kedai, pemasukan konten, perbaikan temuan, presentasi final | F9: 2.6, 3.1, 5.3, 6.3, 7.3, 7.4, 8.2, 9.2 + rapat mingguan | G9: ='Effort Manday'!Q43 -> 15.675
F10: Total | G10: =SUM(G6:G9) -> 64.083333
A12: 2. Matriks tanggung jawab (R = pelaksana utama, S = pendukung, C = dikonsultasikan, I = diinformasikan)
A13: No | B13: Pekerjaan | C13: Andi | D13: Hafiz | E13: Arya | F13: Kharisa | G13: Dosen | H13: Pemilik kedai
A14: 1 | B14: Jadwal dan Gantt Chart | C14: S | D14: R | E14: C | F14: I | G14: I | H14: -
A15: 2 | B15: Resource & Responsibility Plan | C15: R | D15: S | E15: C | F15: C | G15: I | H15: -
A16: 3 | B16: Estimasi manday dan biaya | C16: C | D16: R | E16: C | F16: R | G16: I | H16: -
A17: 4 | B17: Risk Register | C17: S | D17: C | E17: R | F17: C | G17: I | H17: -
A18: 5 | B18: Pengumpulan data menu, harga, foto | C18: S | D18: I | E18: I | F18: R | G18: - | H18: C
A19: 6 | B19: Kebutuhan pengguna dan sistem | C19: R | D19: C | E19: C | F19: S | G19: I | H19: C
A20: 7 | B20: Perancangan struktur dan tampilan | C20: C | D20: C | E20: R | F20: S | G20: I | H20: C
A21: 8 | B21: Pengelolaan repositori GitHub | C21: S | D21: R | E21: S | F21: S | G21: I | H21: -
A22: 9 | B22: Pembuatan tampilan halaman | C22: I | D22: S | E22: R | F22: C | G22: I | H22: -
A23: 10 | B23: Pemasukan konten kedai | C23: I | D23: I | E23: C | F23: R | G23: - | H23: C
A24: 11 | B24: Pengujian dan perbaikan | C24: R | D24: S | E24: R | F24: S | G24: I | H24: C
A25: 12 | B25: Laporan akhir dan evaluasi | C25: R | D25: S | E25: S | F25: S | G25: C | H25: I
A26: 13 | B26: Presentasi final | C26: S | D26: S | E26: S | F26: R | G26: C | H26: -
A28: 3. Kebutuhan sumber daya
A29: No | B29: Sumber daya | C29: Kategori | D29: Jumlah | E29: Status/sumber | F29: Dipakai untuk (kode WBS) | G29: Catatan
A30: 1 | B30: Anggota tim | C30: Manusia | D30: 4 orang | E30: Tersedia | F30: Seluruh aktivitas | G30: Total manday lihat sheet Effort Manday
A31: 2 | B31: Pemilik/pengelola Kedai Pujasera | C31: Manusia (narasumber) | D31: 1 orang | E31: Perlu dijadwalkan | F31: 3.1, 5.3, 6.4 | G31: Sumber data menu, harga, foto, dan masukan
A32: 3 | B32: Dosen pengampu | C32: Manusia (pembimbing) | D32: 1 orang | E32: Tersedia | F32: Seluruh tahap | G32: Arahan dan penilaian
A33: 4 | B33: Laptop/PC | C33: Perangkat | D33: 4 unit | E33: Milik pribadi (asumsi) | F33: 4.x, 5.x, dokumen | G33: Konfirmasi semua anggota memiliki
A34: 5 | B34: Smartphone dengan kamera | C34: Perangkat | D34: minimal 1 | E34: Milik pribadi (asumsi) | F34: 3.1, 5.3 | G34: Untuk foto produk dan dokumentasi
A35: 6 | B35: Git dan GitHub | C35: Layanan | D35: 1 repositori | E35: Gratis | F35: 2.9, 5.4, 7.2 | G35: Bukti kolaborasi Tahap 3
A36: 7 | B36: GitHub Pages | C36: Layanan hosting | D36: 1 situs | E36: Gratis | F36: 5.x, 9.1 | G36: Alternatif hosting bila diperlukan
A37: 8 | B37: Figma/Canva (paket gratis) | C37: Perangkat lunak | D37: 1 akun | E37: Gratis | F37: 4.2 | G37: Wireframe dan mockup
A38: 9 | B38: Editor kode dan peramban | C38: Perangkat lunak | D38: 4 set | E38: Gratis | F38: 5.1–5.3 | G38: Contoh: VS Code
A39: 10 | B39: Aplikasi dokumen dan lembar kerja | C39: Perangkat lunak | D39: 4 set | E39: Tersedia (asumsi) | F39: 2.x, 7.x, 8.x | G39: Word/Excel atau padanannya
A40: 11 | B40: Koneksi internet dan aplikasi pesan | C40: Infrastruktur | D40: 4 akses | E40: Pribadi | F40: Seluruh aktivitas | G40: Rapat daring dan koordinasi
A41: 12 | B41: Akses ke lokasi kedai | C41: Lain-lain | D41: sesuai kebutuhan | E41: Perlu dijadwalkan | F41: 3.1, 6.4 | G41: Pengumpulan data dan uji bersama pemilik

Sheet Effort Manday
A1: Estimasi Usaha (Manday) — Kedai Pujasera Digital
A2: Metode PERT tiga titik: E = (O + 4M + P) ÷ 6. O, M, P adalah perkiraan tim dan bisa diubah (sel biru). Manday = hari kerja satu orang.
A5: No | B5: Kode WBS | C5: Aktivitas | D5: Fase | E5: PIC | F5: Jml orang | G5: O (optimis) | H5: M (paling mungkin) | I5: P (pesimis) | J5: Manday (E) | K5: Durasi otomatis (hari) | L5: Override durasi (hari) | M5: Durasi dipakai (hari) | N5: Andi | O5: Hafiz | P5: Arya | Q5: Kharisa
A6: 1 | B6: 2.3 | C6: Menyusun jadwal kegiatan dan Gantt Chart | D6: Perencanaan | E6: Hafiz | F6: 1 | G6: 1 | H6: 1.5 | I6: 2.5 | J6: =(G6+4*H6+I6)/6 -> 1.5833333 | K6: =ROUNDUP(ROUND(J6/F6,6),0) -> 2 | M6: =IF(L6="",K6,L6) -> 2 | N6: =IF(ISNUMBER(SEARCH(N$5,$E6)),$J6/$F6,0) -> 0 | O6: =IF(ISNUMBER(SEARCH(O$5,$E6)),$J6/$F6,0) -> 1.5833333 | P6: =IF(ISNUMBER(SEARCH(P$5,$E6)),$J6/$F6,0) -> 0 | Q6: =IF(ISNUMBER(SEARCH(Q$5,$E6)),$J6/$F6,0) -> 0
A7: 2 | B7: 2.5 | C7: Menyusun Resource & Responsibility Plan | D7: Perencanaan | E7: Andi | F7: 1 | G7: 1 | H7: 1.5 | I7: 2.5 | J7: =(G7+4*H7+I7)/6 -> 1.5833333 | K7: =ROUNDUP(ROUND(J7/F7,6),0) -> 2 | M7: =IF(L7="",K7,L7) -> 2 | N7: =IF(ISNUMBER(SEARCH(N$5,$E7)),$J7/$F7,0) -> 1.5833333 | O7: =IF(ISNUMBER(SEARCH(O$5,$E7)),$J7/$F7,0) -> 0 | P7: =IF(ISNUMBER(SEARCH(P$5,$E7)),$J7/$F7,0) -> 0 | Q7: =IF(ISNUMBER(SEARCH(Q$5,$E7)),$J7/$F7,0) -> 0
A8: 3 | B8: 2.6 | C8: Menyusun estimasi usaha (manday) | D8: Perencanaan | E8: Kharisa | F8: 1 | G8: 0.5 | H8: 0.8 | I8: 1.2 | J8: =(G8+4*H8+I8)/6 -> 0.81666667 | K8: =ROUNDUP(ROUND(J8/F8,6),0) -> 1 | M8: =IF(L8="",K8,L8) -> 1 | N8: =IF(ISNUMBER(SEARCH(N$5,$E8)),$J8/$F8,0) -> 0 | O8: =IF(ISNUMBER(SEARCH(O$5,$E8)),$J8/$F8,0) -> 0 | P8: =IF(ISNUMBER(SEARCH(P$5,$E8)),$J8/$F8,0) -> 0 | Q8: =IF(ISNUMBER(SEARCH(Q$5,$E8)),$J8/$F8,0) -> 0.81666667
A9: 4 | B9: 2.7 | C9: Menyusun estimasi biaya proyek | D9: Perencanaan | E9: Hafiz | F9: 1 | G9: 0.5 | H9: 0.8 | I9: 1.2 | J9: =(G9+4*H9+I9)/6 -> 0.81666667 | K9: =ROUNDUP(ROUND(J9/F9,6),0) -> 1 | M9: =IF(L9="",K9,L9) -> 1 | N9: =IF(ISNUMBER(SEARCH(N$5,$E9)),$J9/$F9,0) -> 0 | O9: =IF(ISNUMBER(SEARCH(O$5,$E9)),$J9/$F9,0) -> 0.81666667 | P9: =IF(ISNUMBER(SEARCH(P$5,$E9)),$J9/$F9,0) -> 0 | Q9: =IF(ISNUMBER(SEARCH(Q$5,$E9)),$J9/$F9,0) -> 0
A10: 5 | B10: 2.8 | C10: Menyusun Risk Register | D10: Perencanaan | E10: Arya | F10: 1 | G10: 1 | H10: 1.5 | I10: 2.5 | J10: =(G10+4*H10+I10)/6 -> 1.5833333 | K10: =ROUNDUP(ROUND(J10/F10,6),0) -> 2 | M10: =IF(L10="",K10,L10) -> 2 | N10: =IF(ISNUMBER(SEARCH(N$5,$E10)),$J10/$F10,0) -> 0 | O10: =IF(ISNUMBER(SEARCH(O$5,$E10)),$J10/$F10,0) -> 0 | P10: =IF(ISNUMBER(SEARCH(P$5,$E10)),$J10/$F10,0) -> 1.5833333 | Q10: =IF(ISNUMBER(SEARCH(Q$5,$E10)),$J10/$F10,0) -> 0
A11: 6 | B11: 2.9 | C11: Review, kompilasi, dan unggah dokumen Tahap 2 ke GitHub | D11: Perencanaan | E11: Andi, Hafiz | F11: 2 | G11: 0.5 | H11: 1 | I11: 1.5 | J11: =(G11+4*H11+I11)/6 -> 1 | K11: =ROUNDUP(ROUND(J11/F11,6),0) -> 1 | M11: =IF(L11="",K11,L11) -> 1 | N11: =IF(ISNUMBER(SEARCH(N$5,$E11)),$J11/$F11,0) -> 0.5 | O11: =IF(ISNUMBER(SEARCH(O$5,$E11)),$J11/$F11,0) -> 0.5 | P11: =IF(ISNUMBER(SEARCH(P$5,$E11)),$J11/$F11,0) -> 0 | Q11: =IF(ISNUMBER(SEARCH(Q$5,$E11)),$J11/$F11,0) -> 0
A12: 7 | B12: 3.1 | C12: Mengumpulkan data menu, harga, foto, dan informasi kedai | D12: Analisis Kebutuhan | E12: Kharisa | F12: 1 | G12: 2 | H12: 3 | I12: 4 | J12: =(G12+4*H12+I12)/6 -> 3 | K12: =ROUNDUP(ROUND(J12/F12,6),0) -> 3 | M12: =IF(L12="",K12,L12) -> 3 | N12: =IF(ISNUMBER(SEARCH(N$5,$E12)),$J12/$F12,0) -> 0 | O12: =IF(ISNUMBER(SEARCH(O$5,$E12)),$J12/$F12,0) -> 0 | P12: =IF(ISNUMBER(SEARCH(P$5,$E12)),$J12/$F12,0) -> 0 | Q12: =IF(ISNUMBER(SEARCH(Q$5,$E12)),$J12/$F12,0) -> 3
A13: 8 | B13: 3.2 | C13: Menentukan kebutuhan pengguna | D13: Analisis Kebutuhan | E13: Andi | F13: 1 | G13: 1 | H13: 1.5 | I13: 2.5 | J13: =(G13+4*H13+I13)/6 -> 1.5833333 | K13: =ROUNDUP(ROUND(J13/F13,6),0) -> 2 | M13: =IF(L13="",K13,L13) -> 2 | N13: =IF(ISNUMBER(SEARCH(N$5,$E13)),$J13/$F13,0) -> 1.5833333 | O13: =IF(ISNUMBER(SEARCH(O$5,$E13)),$J13/$F13,0) -> 0 | P13: =IF(ISNUMBER(SEARCH(P$5,$E13)),$J13/$F13,0) -> 0 | Q13: =IF(ISNUMBER(SEARCH(Q$5,$E13)),$J13/$F13,0) -> 0
A14: 9 | B14: 3.3 | C14: Menyusun kebutuhan fungsional dan nonfungsional | D14: Analisis Kebutuhan | E14: Andi | F14: 1 | G14: 1 | H14: 1.5 | I14: 2.5 | J14: =(G14+4*H14+I14)/6 -> 1.5833333 | K14: =ROUNDUP(ROUND(J14/F14,6),0) -> 2 | M14: =IF(L14="",K14,L14) -> 2 | N14: =IF(ISNUMBER(SEARCH(N$5,$E14)),$J14/$F14,0) -> 1.5833333 | O14: =IF(ISNUMBER(SEARCH(O$5,$E14)),$J14/$F14,0) -> 0 | P14: =IF(ISNUMBER(SEARCH(P$5,$E14)),$J14/$F14,0) -> 0 | Q14: =IF(ISNUMBER(SEARCH(Q$5,$E14)),$J14/$F14,0) -> 0
A15: 10 | B15: 4.1 | C15: Merancang struktur informasi/halaman | D15: Perancangan | E15: Arya | F15: 1 | G15: 1 | H15: 1.5 | I15: 2.5 | J15: =(G15+4*H15+I15)/6 -> 1.5833333 | K15: =ROUNDUP(ROUND(J15/F15,6),0) -> 2 | M15: =IF(L15="",K15,L15) -> 2 | N15: =IF(ISNUMBER(SEARCH(N$5,$E15)),$J15/$F15,0) -> 0 | O15: =IF(ISNUMBER(SEARCH(O$5,$E15)),$J15/$F15,0) -> 0 | P15: =IF(ISNUMBER(SEARCH(P$5,$E15)),$J15/$F15,0) -> 1.5833333 | Q15: =IF(ISNUMBER(SEARCH(Q$5,$E15)),$J15/$F15,0) -> 0
A16: 11 | B16: 4.2 | C16: Merancang tampilan (wireframe/mockup) | D16: Perancangan | E16: Arya | F16: 1 | G16: 2 | H16: 3 | I16: 4 | J16: =(G16+4*H16+I16)/6 -> 3 | K16: =ROUNDUP(ROUND(J16/F16,6),0) -> 3 | M16: =IF(L16="",K16,L16) -> 3 | N16: =IF(ISNUMBER(SEARCH(N$5,$E16)),$J16/$F16,0) -> 0 | O16: =IF(ISNUMBER(SEARCH(O$5,$E16)),$J16/$F16,0) -> 0 | P16: =IF(ISNUMBER(SEARCH(P$5,$E16)),$J16/$F16,0) -> 3 | Q16: =IF(ISNUMBER(SEARCH(Q$5,$E16)),$J16/$F16,0) -> 0
A17: 12 | B17: 4.3 | C17: Menentukan teknologi yang digunakan | D17: Perancangan | E17: Hafiz | F17: 1 | G17: 0.5 | H17: 0.8 | I17: 1.2 | J17: =(G17+4*H17+I17)/6 -> 0.81666667 | K17: =ROUNDUP(ROUND(J17/F17,6),0) -> 1 | M17: =IF(L17="",K17,L17) -> 1 | N17: =IF(ISNUMBER(SEARCH(N$5,$E17)),$J17/$F17,0) -> 0 | O17: =IF(ISNUMBER(SEARCH(O$5,$E17)),$J17/$F17,0) -> 0.81666667 | P17: =IF(ISNUMBER(SEARCH(P$5,$E17)),$J17/$F17,0) -> 0 | Q17: =IF(ISNUMBER(SEARCH(Q$5,$E17)),$J17/$F17,0) -> 0
... A20: 15 | B20: 5.3 | C20: Memasukkan menu, foto, harga, dan informasi kedai | D20: Pengembangan | E20: Kharisa | F20: 1 | G20: 3 | H20: 4 | I20: 5 | J20: =(G20+4*H20+I20)/6 -> 4 | K20: =ROUNDUP(ROUND(J20/F20,6),0) -> 4 | M20: =IF(L20="",K20,L20) -> 4 | N20: =IF(ISNUMBER(SEARCH(N$5,$E20)),$J20/$F20,0) -> 0 | O20: =IF(ISNUMBER(SEARCH(O$5,$E20)),$J20/$F20,0) -> 0 | P20: =IF(ISNUMBER(SEARCH(P$5,$E20)),$J20/$F20,0) -> 0 | Q20: =IF(ISNUMBER(SEARCH(Q$5,$E20)),$J20/$F20,0) -> 4
A21: 16 | B21: 5.4 | C21: Mengelola versi kode melalui GitHub (berkelanjutan) | D21: Pengembangan | E21: Hafiz | F21: 1 | G21: 2 | H21: 3 | I21: 4 | J21: =(G21+4*H21+I21)/6 -> 3 | K21: =ROUNDUP(ROUND(J21/F21,6),0) -> 3 | L21: 14 | M21: =IF(L21="",K21,L21) -> 14 | N21: =IF(ISNUMBER(SEARCH(N$5,$E21)),$J21/$F21,0) -> 0 | O21: =IF(ISNUMBER(SEARCH(O$5,$E21)),$J21/$F21,0) -> 3 | P21: =IF(ISNUMBER(SEARCH(P$5,$E21)),$J21/$F21,0) -> 0 | Q21: =IF(ISNUMBER(SEARCH(Q$5,$E21)),$J21/$F21,0) -> 0
A22: 17 | B22: 6.1 | C22: Menyusun skenario pengujian | D22: Pengujian | E22: Andi | F22: 1 | G22: 1 | H22: 1.5 | I22: 2.5 | J22: =(G22+4*H22+I22)/6 -> 1.5833333 | K22: =ROUNDUP(ROUND(J22/F22,6),0) -> 2 | M22: =IF(L22="",K22,L22) -> 2 | N22: =IF(ISNUMBER(SEARCH(N$5,$E22)),$J22/$F22,0) -> 1.5833333 | O22: =IF(ISNUMBER(SEARCH(O$5,$E22)),$J22/$F22,0) -> 0 | P22: =IF(ISNUMBER(SEARCH(P$5,$E22)),$J22/$F22,0) -> 0 | Q22: =IF(ISNUMBER(SEARCH(Q$5,$E22)),$J22/$F22,0) -> 0
A23: 18 | B23: 6.2 | C23: Menguji tampilan dan fungsi | D23: Pengujian | E23: Arya, Andi | F23: 2 | G23: 2 | H23: 3 | I23: 4.5 | J23: =(G23+4*H23+I23)/6 -> 3.0833333 | K23: =ROUNDUP(ROUND(J23/F23,6),0) -> 2 | M23: =IF(L23="",K23,L23) -> 2 | N23: =IF(ISNUMBER(SEARCH(N$5,$E23)),$J23/$F23,0) -> 1.5416667 | O23: =IF(ISNUMBER(SEARCH(O$5,$E23)),$J23/$F23,0) -> 0 | P23: =IF(ISNUMBER(SEARCH(P$5,$E23)),$J23/$F23,0) -> 1.5416667 | Q23: =IF(ISNUMBER(SEARCH(Q$5,$E23)),$J23/$F23,0) -> 0
A24: 19 | B24: 6.3 | C24: Memperbaiki temuan pengujian | D24: Pengujian | E24: Kharisa, Hafiz | F24: 2 | G24: 2 | H24: 3 | I24: 4 | J24: =(G24+4*H24+I24)/6 -> 3 | K24: =ROUNDUP(ROUND(J24/F24,6),0) -> 2 | M24: =IF(L24="",K24,L24) -> 2 | N24: =IF(ISNUMBER(SEARCH(N$5,$E24)),$J24/$F24,0) -> 0 | O24: =IF(ISNUMBER(SEARCH(O$5,$E24)),$J24/$F24,0) -> 1.5 | P24: =IF(ISNUMBER(SEARCH(P$5,$E24)),$J24/$F24,0) -> 0 | Q24: =IF(ISNUMBER(SEARCH(Q$5,$E24)),$J24/$F24,0) -> 1.5
A25: 20 | B25: 6.4 | C25: Meminta masukan dari pemilik kedai | D25: Pengujian | E25: Andi | F25: 1 | G25: 0.5 | H25: 0.8 | I25: 1.2 | J25: =(G25+4*H25+I25)/6 -> 0.81666667 | K25: =ROUNDUP(ROUND(J25/F25,6),0) -> 1 | M25: =IF(L25="",K25,L25) -> 1 | N25: =IF(ISNUMBER(SEARCH(N$5,$E25)),$J25/$F25,0) -> 0.81666667 | O25: =IF(ISNUMBER(SEARCH(O$5,$E25)),$J25/$F25,0) -> 0 | P25: =IF(ISNUMBER(SEARCH(P$5,$E25)),$J25/$F25,0) -> 0 | Q25: =IF(ISNUMBER(SEARCH(Q$5,$E25)),$J25/$F25,0) -> 0
A26: 21 | B26: 7.1 | C26: Menyusun laporan akhir proyek | D26: Dokumentasi | E26: Andi | F26: 1 | G26: 3 | H26: 4 | I26: 5 | J26: =(G26+4*H26+I26)/6 -> 4 | K26: =ROUNDUP(ROUND(J26/F26,6),0) -> 4 | M26: =IF(L26="",K26,L26) -> 4 | N26: =IF(ISNUMBER(SEARCH(N$5,$E26)),$J26/$F26,0) -> 4 | O26: =IF(ISNUMBER(SEARCH(O$5,$E26)),$J26/$F26,0) -> 0 | P26: =IF(ISNUMBER(SEARCH(P$5,$E26)),$J26/$F26,0) -> 0 | Q26: =IF(ISNUMBER(SEARCH(Q$5,$E26)),$J26/$F26,0) -> 0
A27: 22 | B27: 7.2 | C27: Mendokumentasikan repositori dan cara penggunaan | D27: Dokumentasi | E27: Hafiz | F27: 1 | G27: 1 | H27: 1.5 | I27: 2.5 | J27: =(G27+4*H27+I27)/6 -> 1.5833333 | K27: =ROUNDUP(ROUND(J27/F27,6),0) -> 2 | M27: =IF(L27="",K27,L27) -> 2 | N27: =IF(ISNUMBER(SEARCH(N$5,$E27)),$J27/$F27,0) -> 0 | O27: =IF(ISNUMBER(SEARCH(O$5,$E27)),$J27/$F27,0) -> 1.5833333 | P27: =IF(ISNUMBER(SEARCH(P$5,$E27)),$J27/$F27,0) -> 0 | Q27: =IF(ISNUMBER(SEARCH(Q$5,$E27)),$J27/$F27,0) -> 0
A28: 23 | B28: 7.3 | C28: Menyiapkan presentasi final | D28: Dokumentasi | E28: Kharisa | F28: 1 | G28: 2 | H28: 3 | I28: 4 | J28: =(G28+4*H28+I28)/6 -> 3 | K28: =ROUNDUP(ROUND(J28/F28,6),0) -> 3 | M28: =IF(L28="",K28,L28) -> 3 | N28: =IF(ISNUMBER(SEARCH(N$5,$E28)),$J28/$F28,0) -> 0 | O28: =IF(ISNUMBER(SEARCH(O$5,$E28)),$J28/$F28,0) -> 0 | P28: =IF(ISNUMBER(SEARCH(P$5,$E28)),$J28/$F28,0) -> 0 | Q28: =IF(ISNUMBER(SEARCH(Q$5,$E28)),$J28/$F28,0) -> 3
A29: 24 | B29: 7.4 | C29: Menyusun evaluasi pencapaian dan Lessons Learned | D29: Dokumentasi | E29: Arya, Kharisa | F29: 2 | G29: 1 | H29: 1.5 | I29: 2.5 | J29: =(G29+4*H29+I29)/6 -> 1.5833333 | K29: =ROUNDUP(ROUND(J29/F29,6),0) -> 1 | M29: =IF(L29="",K29,L29) -> 1 | N29: =IF(ISNUMBER(SEARCH(N$5,$E29)),$J29/$F29,0) -> 0 | O29: =IF(ISNUMBER(SEARCH(O$5,$E29)),$J29/$F29,0) -> 0 | P29: =IF(ISNUMBER(SEARCH(P$5,$E29)),$J29/$F29,0) -> 0.79166667 | Q29: =IF(ISNUMBER(SEARCH(Q$5,$E29)),$J29/$F29,0) -> 0.79166667
A30: 25 | B30: 8.1 | C30: Rekap rencana vs realisasi waktu | D30: Monitoring & Controlling | E30: Hafiz | F30: 1 | G30: 0.5 | H30: 0.8 | I30: 1.2 | J30: =(G30+4*H30+I30)/6 -> 0.81666667 | K30: =ROUNDUP(ROUND(J30/F30,6),0) -> 1 | M30: =IF(L30="",K30,L30) -> 1 | N30: =IF(ISNUMBER(SEARCH(N$5,$E30)),$J30/$F30,0) -> 0 | O30: =IF(ISNUMBER(SEARCH(O$5,$E30)),$J30/$F30,0) -> 0.81666667 | P30: =IF(ISNUMBER(SEARCH(P$5,$E30)),$J30/$F30,0) -> 0 | Q30: =IF(ISNUMBER(SEARCH(Q$5,$E30)),$J30/$F30,0) -> 0
A31: 26 | B31: 8.2 | C31: Rekap manday estimasi vs aktual | D31: Monitoring & Controlling | E31: Kharisa | F31: 1 | G31: 0.5 | H31: 0.8 | I31: 1.2 | J31: =(G31+4*H31+I31)/6 -> 0.81666667 | K31: =ROUNDUP(ROUND(J31/F31,6),0) -> 1 | M31: =IF(L31="",K31,L31) -> 1 | N31: =IF(ISNUMBER(SEARCH(N$5,$E31)),$J31/$F31,0) -> 0 | O31: =IF(ISNUMBER(SEARCH(O$5,$E31)),$J31/$F31,0) -> 0 | P31: =IF(ISNUMBER(SEARCH(P$5,$E31)),$J31/$F31,0) -> 0 | Q31: =IF(ISNUMBER(SEARCH(Q$5,$E31)),$J31/$F31,0) -> 0.81666667
A32: 27 | B32: 8.3 | C32: Rekap anggaran vs biaya aktual | D32: Monitoring & Controlling | E32: Andi | F32: 1 | G32: 0.5 | H32: 0.8 | I32: 1.2 | J32: =(G32+4*H32+I32)/6 -> 0.81666667 | K32: =ROUNDUP(ROUND(J32/F32,6),0) -> 1 | M32: =IF(L32="",K32,L32) -> 1 | N32: =IF(ISNUMBER(SEARCH(N$5,$E32)),$J32/$F32,0) -> 0.81666667 | O32: =IF(ISNUMBER(SEARCH(O$5,$E32)),$J32/$F32,0) -> 0 | P32: =IF(ISNUMBER(SEARCH(P$5,$E32)),$J32/$F32,0) -> 0 | Q32: =IF(ISNUMBER(SEARCH(Q$5,$E32)),$J32/$F32,0) -> 0
A33: 28 | B33: 8.4 | C33: Daftar masalah, perubahan ruang lingkup, dan tindakan korektif | D33: Monitoring & Controlling | E33: Arya | F33: 1 | G33: 0.5 | H33: 0.8 | I33: 1.2 | J33: =(G33+4*H33+I33)/6 -> 0.81666667 | K33: =ROUNDUP(ROUND(J33/F33,6),0) -> 1 | M33: =IF(L33="",K33,L33) -> 1 | N33: =IF(ISNUMBER(SEARCH(N$5,$E33)),$J33/$F33,0) -> 0 | O33: =IF(ISNUMBER(SEARCH(O$5,$E33)),$J33/$F33,0) -> 0 | P33: =IF(ISNUMBER(SEARCH(P$5,$E33)),$J33/$F33,0) -> 0.81666667 | Q33: =IF(ISNUMBER(SEARCH(Q$5,$E33)),$J33/$F33,0) -> 0
... A42: 37 | B42: R6 | C42: Rapat koordinasi dan notulen minggu ke-6 | D42: Koordinasi Tim | E42: Andi, Hafiz, Arya, Kharisa | F42: 4 | G42: 0.8 | H42: 1 | I42: 1.2 | J42: =(G42+4*H42+I42)/6 -> 1 | K42: =ROUNDUP(ROUND(J42/F42,6),0) -> 1 | M42: =IF(L42="",K42,L42) -> 1 | N42: =IF(ISNUMBER(SEARCH(N$5,$E42)),$J42/$F42,0) -> 0.25 | O42: =IF(ISNUMBER(SEARCH(O$5,$E42)),$J42/$F42,0) -> 0.25 | P42: =IF(ISNUMBER(SEARCH(P$5,$E42)),$J42/$F42,0) -> 0.25 | Q42: =IF(ISNUMBER(SEARCH(Q$5,$E42)),$J42/$F42,0) -> 0.25
C43: TOTAL | J43: =SUM(J6:J42) -> 64.083333 | N43: =SUM(N6:N42) -> 16.575 | O43: =SUM(O6:O42) -> 14.225 | P43: =SUM(P6:P42) -> 17.608333 | Q43: =SUM(Q6:Q42) -> 15.675
C44: Cek: total manday per anggota = total manday proyek | J44: =IF(ABS(SUM(N43:Q43)-J43)<0.001,"OK","SELISIH") -> OK
C46: Rekap manday per fase | D46: Manday | E46: % total
C47: Perencanaan | D47: =SUMIFS($J$6:$J$42,$D$6:$D$42,C47) -> 7.3833333 | E47: =D47/$J$43 -> 0.11521456
C48: Analisis Kebutuhan | D48: =SUMIFS($J$6:$J$42,$D$6:$D$42,C48) -> 6.1666667 | E48: =D48/$J$43 -> 0.096228869
C49: Perancangan | D49: =SUMIFS($J$6:$J$42,$D$6:$D$42,C49) -> 5.4 | E49: =D49/$J$43 -> 0.08426528
C50: Pengembangan | D50: =SUMIFS($J$6:$J$42,$D$6:$D$42,C50) -> 13.316667 | E50: =D50/$J$43 -> 0.20780234
C51: Pengujian | D51: =SUMIFS($J$6:$J$42,$D$6:$D$42,C51) -> 8.4833333 | E51: =D51/$J$43 -> 0.13237971
C52: Dokumentasi | D52: =SUMIFS($J$6:$J$42,$D$6:$D$42,C52) -> 10.166667 | E52: =D52/$J$43 -> 0.15864759
C53: Monitoring & Controlling | D53: =SUMIFS($J$6:$J$42,$D$6:$D$42,C53) -> 4.0833333 | E53: =D53/$J$43 -> 0.063719116
...

Sheet Biaya
A1: Project Cost Estimation — Kedai Pujasera Digital
A2: Rupiah (Rp). Sel biru = asumsi yang boleh diganti. Tenaga kerja dihitung sebagai nilai setara (nonkas); pengeluaran tunai dipisahkan di ringkasan.
A4: Asumsi kunci
A5: Tarif tenaga kerja per manday (Rp) | E5: 100000
A6: Cadangan/kontingensi (% dari biaya langsung dan overhead) | E6: 0.1
A8: A. Biaya tenaga kerja (nilai setara, nonkas)
A9: Anggota | B9: Peran | C9: Manday | D9: Tarif/manday | E9: Biaya (Rp)
A10: Andi Saputra | B10: Analis kebutuhan dan penyusun laporan | C10: ='Effort Manday'!N43 -> 16.575 | D10: =$E$5 -> 100000 | E10: =C10*D10 -> 1657500
A11: Muhammad Hafiz Akbar | B11: Pengelola repositori dan pengembang | C11: ='Effort Manday'!O43 -> 14.225 | D11: =$E$5 -> 100000 | E11: =C11*D11 -> 1422500
A12: Arya Diansyah | B12: Perancang tampilan dan pengembang UI | C12: ='Effort Manday'!P43 -> 17.608333 | D12: =$E$5 -> 100000 | E12: =C12*D12 -> 1760833.3
A13: Kharisa Ariyana | B13: Pengelola konten dan presentasi | C13: ='Effort Manday'!Q43 -> 15.675 | D13: =$E$5 -> 100000 | E13: =C13*D13 -> 1567500
A14: Subtotal A | C14: =SUM(C10:C13) -> 64.083333 | E14: =SUM(E10:E13) -> 6408333.3
A16: B. Perangkat dan layanan
A17: Item | B17: Jumlah | C17: Satuan | D17: Harga satuan (Rp) | E17: Periode (kali/bulan) | F17: Total (Rp) | G17: Jenis | H17: Catatan
A18: Laptop/PC anggota | B18: 4 | C18: unit | D18: 0 | E18: 1 | F18: =B18*D18*E18 -> 0 | G18: Nonkas | H18: Milik pribadi, tidak ada pembelian
A19: Smartphone (foto produk dan dokumentasi) | B19: 1 | C19: unit | D19: 0 | E19: 1 | F19: =B19*D19*E19 -> 0 | G19: Nonkas | H19: Milik pribadi
A20: GitHub (akun dan repositori) | B20: 1 | C20: layanan | D20: 0 | E20: 1 | F20: =B20*D20*E20 -> 0 | G20: Nonkas | H20: Paket gratis
A21: GitHub Pages (hosting) | B21: 1 | C21: layanan | D21: 0 | E21: 1 | F21: =B21*D21*E21 -> 0 | G21: Nonkas | H21: Gratis
A22: Figma/Canva (rancangan tampilan) | B22: 1 | C22: layanan | D22: 0 | E22: 1 | F22: =B22*D22*E22 -> 0 | G22: Nonkas | H22: Paket gratis
A23: Domain kustom (opsional) | B23: 0 | C23: tahun | D23: 0 | E23: 1 | F23: =B23*D23*E23 -> 0 | G23: Kas | H23: Isi jumlah dan harga bila kelompok memutuskan memakai domain sendiri
A24: Kuota internet | B24: 4 | C24: orang | D24: 75000 | E24: 2 | F24: =B24*D24*E24 -> 600000 | G24: Kas | H24: Asumsi Rp75.000 per orang per bulan selama 2 bulan
A25: Subtotal | F25: =SUM(F18:F24) -> 600000
A27: C. Overhead dan operasional
A28: Item | B28: Jumlah | C28: Satuan | D28: Harga satuan (Rp) | E28: Periode (kali/bulan) | F28: Total (Rp) | G28: Jenis | H28: Catatan
A29: Transportasi ke kedai (pengumpulan data, foto, uji) | B29: 3 | C29: kunjungan | D29: 50000 | E29: 1 | F29: =B29*D29*E29 -> 150000 | G29: Kas | H29: Asumsi 3 kunjungan, Rp50.000 per kunjungan; sesuaikan
A30: Cetak dan penjilidan dokumen | B30: 1 | C30: paket | D30: 50000 | E30: 1 | F30: =B30*D30*E30 -> 50000 | G30: Kas | H30: Asumsi, bila dosen meminta cetak
A31: Subtotal | F31: =SUM(F29:F30) -> 200000
A33: D. Ringkasan anggaran (baseline)
A34: Komponen | E34: Jumlah (Rp)
A35: A. Tenaga kerja (nilai setara) | E35: =E14 -> 6408333.3
A36: B. Perangkat dan layanan | E36: =F25 -> 600000
A37: C. Overhead dan operasional | E37: =F31 -> 200000
A38: Subtotal | E38: =SUM(E35:E37) -> 7208333.3
A39: Cadangan/kontingensi | E39: =E38*$E$6 -> 720833.33
A40: TOTAL ANGGARAN PROYEK (BASELINE) | E40: =E38+E39 -> 7929166.7
A42: Dari total itu, pengeluaran tunai langsung (jenis Kas) | E42: =SUMIFS(F18:F24,G18:G24,"Kas")+SUMIFS(F29:F30,G29:G30,"Kas") -> 800000
A43: Nilai tenaga kerja (nonkas, tidak dibayarkan) | E43: =E14 -> 6408333.3
A45: Catatan: baseline ini dipakai pada Tahap 4 untuk membandingkan anggaran dengan biaya aktual.

Sheet Risk Register
A1: Risk Register — Kedai Pujasera Digital
A2: Skor = probabilitas × dampak (skala 1–5). Tingkat: ≥15 Tinggi, 8–14 Sedang, <8 Rendah. Nilai P dan I adalah penilaian awal tim (sel biru).
A4: ID | B4: Risiko | C4: Penyebab | D4: Kode WBS | E4: Probabilitas (1–5) | F4: Dampak (1–5) | G4: Skor | H4: Tingkat | I4: Strategi | J4: Rencana mitigasi | K4: Pemilik risiko | L4: Indikator/pemicu | M4: Status
A5: R01 | B5: Data menu, harga, dan foto kedai terlambat atau tidak lengkap | C5: Pemilik sibuk atau jadwal kunjungan tidak cocok | D5: 3.1, 5.3 | E5: 4 | F5: 4 | G5: =E5*F5 -> 16 | H5: =IF(G5>=15,"Tinggi",IF(G5>=8,"Sedang","Rendah")) -> Tinggi | I5: Kurangi | J5: Kirim daftar isian data sejak awal, jadwalkan kunjungan di minggu pertama, siapkan data sementara agar pengembangan tidak berhenti | K5: Kharisa | L5: Data belum lengkap pada 28 Okt | M5: Terbuka
A6: R02 | B6: Jadwal proyek bentrok dengan kuliah dan tugas lain | C6: Tenggat mata kuliah lain berdekatan | D6: Semua | E6: 4 | F6: 3 | G6: =E6*F6 -> 12 | H6: =IF(G6>=15,"Tinggi",IF(G6>=8,"Sedang","Rendah")) -> Sedang | I6: Kurangi | J6: Rapat mingguan untuk menata ulang beban, beri ruang cadangan pada jadwal, utamakan jalur kritis | K6: Andi | L6: Aktivitas mundur lebih dari 2 hari kerja | M6: Terbuka
A7: R03 | B7: Estimasi manday dan durasi terlalu optimis | C7: Perkiraan O, M, P belum teruji | D7: 2.6, 2.3 | E7: 3 | F7: 4 | G7: =E7*F7 -> 12 | H7: =IF(G7>=15,"Tinggi",IF(G7>=8,"Sedang","Rendah")) -> Sedang | I7: Kurangi | J7: Pakai PERT tiga titik, tinjau tiap minggu, perbarui estimasi pada Tahap 4 | K7: Hafiz | L7: Manday aktual melebihi estimasi 20% | M7: Terbuka
A8: R04 | B8: Perubahan ruang lingkup (mis. pemilik meminta pemesanan online) | C8: Harapan pemilik berkembang di tengah proyek | D8: 3.2, 4.x | E8: 3 | F8: 4 | G8: =E8*F8 -> 12 | H8: =IF(G8>=15,"Tinggi",IF(G8>=8,"Sedang","Rendah")) -> Sedang | I8: Hindari | J8: Catat sebagai permintaan perubahan, nilai dampak waktu dan biaya, putuskan bersama dosen; tetap pada ruang lingkup Project Charter | K8: Andi | L8: Ada permintaan fitur di luar charter | M8: Terbuka
A9: R05 | B9: Anggota berhalangan (sakit atau keperluan keluarga) | C9: Kondisi tak terduga | D9: Semua | E9: 3 | F9: 4 | G9: =E9*F9 -> 12 | H9: =IF(G9>=15,"Tinggi",IF(G9>=8,"Sedang","Rendah")) -> Sedang | I9: Kurangi | J9: Dokumentasikan pekerjaan di GitHub, tentukan anggota pendukung tiap tugas (lihat matriks RACI) | K9: Andi | L9: Anggota tidak aktif lebih dari 3 hari | M9: Terbuka
A10: R06 | B10: Cacat ditemukan banyak saat pengujian dan mepet tenggat | C10: Pengujian baru dilakukan di akhir | D10: 6.2, 6.3 | E10: 3 | F10: 4 | G10: =E10*F10 -> 12 | H10: =IF(G10>=15,"Tinggi",IF(G10>=8,"Sedang","Rendah")) -> Sedang | I10: Kurangi | J10: Uji bertahap sejak 5.2, sisakan 2 hari perbaikan sebelum penutupan | K10: Arya | L10: Lebih dari 10 temuan pada 6.2 | M10: Terbuka
A11: R07 | B11: Anggota belum terbiasa Git/GitHub sehingga berkas tertimpa atau konflik | C11: Pengalaman Git terbatas | D11: 5.4 | E11: 3 | F11: 3 | G11: =E11*F11 -> 9 | H11: =IF(G11>=15,"Tinggi",IF(G11>=8,"Sedang","Rendah")) -> Sedang | I11: Kurangi | J11: Latihan bersama, aturan branch dan pull request, commit kecil dan sering | K11: Hafiz | L11: Konflik penggabungan berulang | M11: Terbuka
A12: R08 | B12: Koneksi internet tidak stabil saat unggah atau rapat daring | C12: Gangguan jaringan | D12: Semua | E12: 3 | F12: 3 | G12: =E12*F12 -> 9 | H12: =IF(G12>=15,"Tinggi",IF(G12>=8,"Sedang","Rendah")) -> Sedang | I12: Terima | J12: Commit lokal lalu push saat koneksi baik, rapat tatap muka bila perlu | K12: Hafiz | L12: Unggah gagal lebih dari 2 kali | M12: Terbuka
A13: R09 | B13: Menu atau harga berubah setelah data dikumpulkan | C13: Penyesuaian harga oleh pemilik | D13: 5.3 | E13: 4 | F13: 2 | G13: =E13*F13 -> 8 | H13: =IF(G13>=15,"Tinggi",IF(G13>=8,"Sedang","Rendah")) -> Sedang | I13: Kurangi | J13: Konfirmasi ulang sebelum pemasukan konten, rancang konten agar mudah diperbarui | K13: Kharisa | L13: Pemilik menyebut perubahan harga | M13: Terbuka
A14: R10 | B14: Harapan pemilik berbeda dengan rancangan tim | C14: Rancangan tidak ditunjukkan lebih awal | D14: 4.2, 6.4 | E14: 2 | F14: 4 | G14: =E14*F14 -> 8 | H14: =IF(G14>=15,"Tinggi",IF(G14>=8,"Sedang","Rendah")) -> Sedang | I14: Kurangi | J14: Tunjukkan wireframe lebih awal dan minta persetujuan sebelum pengembangan | K14: Arya | L14: Pemilik meminta perubahan besar pada tampilan | M14: Terbuka
A15: R11 | B15: Berkas lokal hilang atau rusak | C15: Kerusakan perangkat atau salah hapus | D15: Semua | E15: 2 | F15: 4 | G15: =E15*F15 -> 8 | H15: =IF(G15>=15,"Tinggi",IF(G15>=8,"Sedang","Rendah")) -> Sedang | I15: Kurangi | J15: Simpan di GitHub dan cadangan di penyimpanan daring | K15: Hafiz | L15: Berkas belum ter-push lebih dari 3 hari | M15: Terbuka
A16: R12 | B16: Foto produk kurang berkualitas | C16: Pencahayaan dan latar tidak sesuai | D16: 3.1, 5.3 | E16: 3 | F16: 2 | G16: =E16*F16 -> 6 | H16: =IF(G16>=15,"Tinggi",IF(G16>=8,"Sedang","Rendah")) -> Rendah | I16: Kurangi | J16: Panduan sederhana pencahayaan, ambil ulang foto bila perlu | K16: Kharisa | L16: Foto buram atau gelap | M16: Terbuka
A17: R13 | B17: Layanan hosting gratis tidak tersedia atau bermasalah | C17: Kebijakan layanan berubah | D17: 5.x, 9.1 | E17: 1 | F17: 3 | G17: =E17*F17 -> 3 | H17: =IF(G17>=15,"Tinggi",IF(G17>=8,"Sedang","Rendah")) -> Rendah | I17: Terima | J17: Siapkan alternatif hosting gratis lain | K17: Hafiz | L17: Situs tidak bisa diakses | M17: Terbuka
B19: Ringkasan
B20: Jumlah risiko tingkat Tinggi | C20: =COUNTIF($H$5:$H$17,"Tinggi") -> 1
B21: Jumlah risiko tingkat Sedang | C21: =COUNTIF($H$5:$H$17,"Sedang") -> 10
B22: Jumlah risiko tingkat Rendah | C22: =COUNTIF($H$5:$H$17,"Rendah") -> 2
B24: Strategi: Hindari = ubah rencana agar risiko tidak terjadi; Kurangi = turunkan peluang/dampak; Terima = dipantau saja. Status risiko diperbarui pada Tahap 4.
